2018-09-14 09:37:18,085 ERROR: Exception on /edit_profile [GET] [in /www/blog/venv/lib/python3.6/site-packages/flask/app.py:1761]
Traceback (most recent call last):
  File "/www/blog/venv/lib/python3.6/site-packages/flask/app.py", line 2292, in wsgi_app
    response = self.full_dispatch_request()
  File "/www/blog/venv/lib/python3.6/site-packages/flask/app.py", line 1815, in full_dispatch_request
    rv = self.handle_user_exception(e)
  File "/www/blog/venv/lib/python3.6/site-packages/flask/app.py", line 1718, in handle_user_exception
    reraise(exc_type, exc_value, tb)
  File "/www/blog/venv/lib/python3.6/site-packages/flask/_compat.py", line 35, in reraise
    raise value
  File "/www/blog/venv/lib/python3.6/site-packages/flask/app.py", line 1813, in full_dispatch_request
    rv = self.dispatch_request()
  File "/www/blog/venv/lib/python3.6/site-packages/flask/app.py", line 1799, in dispatch_request
    return self.view_functions[rule.endpoint](**req.view_args)
  File "/www/blog/venv/lib/python3.6/site-packages/flask_login/utils.py", line 261, in decorated_view
    return func(*args, **kwargs)
  File "/www/blog/app/routes.py", line 94, in edit_profile
    form = EditProfileForm(current_user.username)
  File "/www/blog/venv/lib/python3.6/site-packages/wtforms/form.py", line 212, in __call__
    return type.__call__(cls, *args, **kwargs)
  File "/www/blog/app/forms.py", line 37, in __init__
    self.original_username = original_username
NameError: name 'original_username' is not defined
2018-09-14 09:38:30,177 ERROR: Exception on /edit_profile [GET] [in /www/blog/venv/lib/python3.6/site-packages/flask/app.py:1761]
Traceback (most recent call last):
  File "/www/blog/venv/lib/python3.6/site-packages/flask/app.py", line 2292, in wsgi_app
    response = self.full_dispatch_request()
  File "/www/blog/venv/lib/python3.6/site-packages/flask/app.py", line 1815, in full_dispatch_request
    rv = self.handle_user_exception(e)
  File "/www/blog/venv/lib/python3.6/site-packages/flask/app.py", line 1718, in handle_user_exception
    reraise(exc_type, exc_value, tb)
  File "/www/blog/venv/lib/python3.6/site-packages/flask/_compat.py", line 35, in reraise
    raise value
  File "/www/blog/venv/lib/python3.6/site-packages/flask/app.py", line 1813, in full_dispatch_request
    rv = self.dispatch_request()
  File "/www/blog/venv/lib/python3.6/site-packages/flask/app.py", line 1799, in dispatch_request
    return self.view_functions[rule.endpoint](**req.view_args)
  File "/www/blog/venv/lib/python3.6/site-packages/flask_login/utils.py", line 261, in decorated_view
    return func(*args, **kwargs)
  File "/www/blog/app/routes.py", line 94, in edit_profile
    form = EditProfileForm(current_user.username)
  File "/www/blog/venv/lib/python3.6/site-packages/wtforms/form.py", line 212, in __call__
    return type.__call__(cls, *args, **kwargs)
  File "/www/blog/app/forms.py", line 37, in __init__
    self.original_username = original_username
NameError: name 'original_username' is not defined
2018-09-14 09:38:31,253 ERROR: Exception on /edit_profile [GET] [in /www/blog/venv/lib/python3.6/site-packages/flask/app.py:1761]
Traceback (most recent call last):
  File "/www/blog/venv/lib/python3.6/site-packages/flask/app.py", line 2292, in wsgi_app
    response = self.full_dispatch_request()
  File "/www/blog/venv/lib/python3.6/site-packages/flask/app.py", line 1815, in full_dispatch_request
    rv = self.handle_user_exception(e)
  File "/www/blog/venv/lib/python3.6/site-packages/flask/app.py", line 1718, in handle_user_exception
    reraise(exc_type, exc_value, tb)
  File "/www/blog/venv/lib/python3.6/site-packages/flask/_compat.py", line 35, in reraise
    raise value
  File "/www/blog/venv/lib/python3.6/site-packages/flask/app.py", line 1813, in full_dispatch_request
    rv = self.dispatch_request()
  File "/www/blog/venv/lib/python3.6/site-packages/flask/app.py", line 1799, in dispatch_request
    return self.view_functions[rule.endpoint](**req.view_args)
  File "/www/blog/venv/lib/python3.6/site-packages/flask_login/utils.py", line 261, in decorated_view
    return func(*args, **kwargs)
  File "/www/blog/app/routes.py", line 94, in edit_profile
    form = EditProfileForm(current_user.username)
  File "/www/blog/venv/lib/python3.6/site-packages/wtforms/form.py", line 212, in __call__
    return type.__call__(cls, *args, **kwargs)
  File "/www/blog/app/forms.py", line 37, in __init__
    self.original_username = original_username
NameError: name 'original_username' is not defined
2018-09-14 09:38:33,781 ERROR: Exception on /edit_profile [GET] [in /www/blog/venv/lib/python3.6/site-packages/flask/app.py:1761]
Traceback (most recent call last):
  File "/www/blog/venv/lib/python3.6/site-packages/flask/app.py", line 2292, in wsgi_app
    response = self.full_dispatch_request()
  File "/www/blog/venv/lib/python3.6/site-packages/flask/app.py", line 1815, in full_dispatch_request
    rv = self.handle_user_exception(e)
  File "/www/blog/venv/lib/python3.6/site-packages/flask/app.py", line 1718, in handle_user_exception
    reraise(exc_type, exc_value, tb)
  File "/www/blog/venv/lib/python3.6/site-packages/flask/_compat.py", line 35, in reraise
    raise value
  File "/www/blog/venv/lib/python3.6/site-packages/flask/app.py", line 1813, in full_dispatch_request
    rv = self.dispatch_request()
  File "/www/blog/venv/lib/python3.6/site-packages/flask/app.py", line 1799, in dispatch_request
    return self.view_functions[rule.endpoint](**req.view_args)
  File "/www/blog/venv/lib/python3.6/site-packages/flask_login/utils.py", line 261, in decorated_view
    return func(*args, **kwargs)
  File "/www/blog/app/routes.py", line 94, in edit_profile
    form = EditProfileForm(current_user.username)
  File "/www/blog/venv/lib/python3.6/site-packages/wtforms/form.py", line 212, in __call__
    return type.__call__(cls, *args, **kwargs)
  File "/www/blog/app/forms.py", line 37, in __init__
    self.original_username = original_username
NameError: name 'original_username' is not defined
2018-09-14 09:38:44,630 INFO: Microblog startup [in /www/blog/app/__init__.py:47]
2018-09-14 10:31:38,204 INFO: Microblog startup [in /www/blog/app/__init__.py:47]
2018-09-14 10:37:17,460 INFO: Microblog startup [in /www/blog/app/__init__.py:47]
2018-09-14 10:39:40,059 INFO: Microblog startup [in /www/blog/app/__init__.py:47]
2018-09-14 11:01:50,122 INFO: Microblog startup [in /www/blog/app/__init__.py:47]
2018-09-14 11:01:56,079 ERROR: Exception on /explore [GET] [in /www/blog/venv/lib/python3.6/site-packages/flask/app.py:1761]
Traceback (most recent call last):
  File "/www/blog/venv/lib/python3.6/site-packages/flask/app.py", line 2292, in wsgi_app
    response = self.full_dispatch_request()
  File "/www/blog/venv/lib/python3.6/site-packages/flask/app.py", line 1815, in full_dispatch_request
    rv = self.handle_user_exception(e)
  File "/www/blog/venv/lib/python3.6/site-packages/flask/app.py", line 1718, in handle_user_exception
    reraise(exc_type, exc_value, tb)
  File "/www/blog/venv/lib/python3.6/site-packages/flask/_compat.py", line 35, in reraise
    raise value
  File "/www/blog/venv/lib/python3.6/site-packages/flask/app.py", line 1813, in full_dispatch_request
    rv = self.dispatch_request()
  File "/www/blog/venv/lib/python3.6/site-packages/flask/app.py", line 1799, in dispatch_request
    return self.view_functions[rule.endpoint](**req.view_args)
  File "/www/blog/venv/lib/python3.6/site-packages/flask_login/utils.py", line 261, in decorated_view
    return func(*args, **kwargs)
  File "/www/blog/app/routes.py", line 136, in explore
    return render_template('index.html', title='Explore', posts=posts)
  File "/www/blog/venv/lib/python3.6/site-packages/flask/templating.py", line 135, in render_template
    context, ctx.app)
  File "/www/blog/venv/lib/python3.6/site-packages/flask/templating.py", line 117, in _render
    rv = template.render(context)
  File "/www/blog/venv/lib/python3.6/site-packages/jinja2/asyncsupport.py", line 76, in render
    return original_render(self, *args, **kwargs)
  File "/www/blog/venv/lib/python3.6/site-packages/jinja2/environment.py", line 1008, in render
    return self.environment.handle_exception(exc_info, True)
  File "/www/blog/venv/lib/python3.6/site-packages/jinja2/environment.py", line 780, in handle_exception
    reraise(exc_type, exc_value, tb)
  File "/www/blog/venv/lib/python3.6/site-packages/jinja2/_compat.py", line 37, in reraise
    raise value.with_traceback(tb)
  File "/www/blog/app/templates/index.html", line 1, in top-level template code
    {% extends "base.html" %}
  File "/www/blog/app/templates/base.html", line 23, in top-level template code
    {% block content %}{% endblock %}
  File "/www/blog/app/templates/index.html", line 20, in block "content"
    {% for post in posts%}
TypeError: 'Pagination' object is not iterable
