2018-09-14 13:56:22,660 ERROR: Exception on /reset_password_request [POST] [in /www/blog/venv/lib/python3.6/site-packages/flask/app.py:1761]
Traceback (most recent call last):
  File "/www/blog/venv/lib/python3.6/site-packages/flask/app.py", line 2292, in wsgi_app
    response = self.full_dispatch_request()
  File "/www/blog/venv/lib/python3.6/site-packages/flask/app.py", line 1815, in full_dispatch_request
    rv = self.handle_user_exception(e)
  File "/www/blog/venv/lib/python3.6/site-packages/flask/app.py", line 1718, in handle_user_exception
    reraise(exc_type, exc_value, tb)
  File "/www/blog/venv/lib/python3.6/site-packages/flask/_compat.py", line 35, in reraise
    raise value
  File "/www/blog/venv/lib/python3.6/site-packages/flask/app.py", line 1813, in full_dispatch_request
    rv = self.dispatch_request()
  File "/www/blog/venv/lib/python3.6/site-packages/flask/app.py", line 1799, in dispatch_request
    return self.view_functions[rule.endpoint](**req.view_args)
  File "/www/blog/app/routes.py", line 167, in reset_password_request
    send_password_reset_email(user)
  File "/www/blog/app/email.py", line 13, in send_password_reset_email
    sender=app.config['ADMINS'][0],
NameError: name 'app' is not defined
2018-09-14 13:56:56,863 ERROR: Exception on /reset_password_request [POST] [in /www/blog/venv/lib/python3.6/site-packages/flask/app.py:1761]
Traceback (most recent call last):
  File "/www/blog/venv/lib/python3.6/site-packages/flask/app.py", line 2292, in wsgi_app
    response = self.full_dispatch_request()
  File "/www/blog/venv/lib/python3.6/site-packages/flask/app.py", line 1815, in full_dispatch_request
    rv = self.handle_user_exception(e)
  File "/www/blog/venv/lib/python3.6/site-packages/flask/app.py", line 1718, in handle_user_exception
    reraise(exc_type, exc_value, tb)
  File "/www/blog/venv/lib/python3.6/site-packages/flask/_compat.py", line 35, in reraise
    raise value
  File "/www/blog/venv/lib/python3.6/site-packages/flask/app.py", line 1813, in full_dispatch_request
    rv = self.dispatch_request()
  File "/www/blog/venv/lib/python3.6/site-packages/flask/app.py", line 1799, in dispatch_request
    return self.view_functions[rule.endpoint](**req.view_args)
  File "/www/blog/app/routes.py", line 167, in reset_password_request
    send_password_reset_email(user)
  File "/www/blog/app/email.py", line 13, in send_password_reset_email
    sender=app.config['ADMINS'][0],
NameError: name 'app' is not defined
2018-09-14 13:57:02,978 ERROR: Exception on /reset_password_request [POST] [in /www/blog/venv/lib/python3.6/site-packages/flask/app.py:1761]
Traceback (most recent call last):
  File "/www/blog/venv/lib/python3.6/site-packages/flask/app.py", line 2292, in wsgi_app
    response = self.full_dispatch_request()
  File "/www/blog/venv/lib/python3.6/site-packages/flask/app.py", line 1815, in full_dispatch_request
    rv = self.handle_user_exception(e)
  File "/www/blog/venv/lib/python3.6/site-packages/flask/app.py", line 1718, in handle_user_exception
    reraise(exc_type, exc_value, tb)
  File "/www/blog/venv/lib/python3.6/site-packages/flask/_compat.py", line 35, in reraise
    raise value
  File "/www/blog/venv/lib/python3.6/site-packages/flask/app.py", line 1813, in full_dispatch_request
    rv = self.dispatch_request()
  File "/www/blog/venv/lib/python3.6/site-packages/flask/app.py", line 1799, in dispatch_request
    return self.view_functions[rule.endpoint](**req.view_args)
  File "/www/blog/app/routes.py", line 167, in reset_password_request
    send_password_reset_email(user)
  File "/www/blog/app/email.py", line 13, in send_password_reset_email
    sender=app.config['ADMINS'][0],
NameError: name 'app' is not defined
2018-09-14 13:57:48,182 INFO: Microblog startup [in /www/blog/app/__init__.py:47]
2018-09-14 13:58:01,503 ERROR: Exception on /reset_password_request [POST] [in /www/blog/venv/lib/python3.6/site-packages/flask/app.py:1761]
Traceback (most recent call last):
  File "/www/blog/venv/lib/python3.6/site-packages/flask/app.py", line 2292, in wsgi_app
    response = self.full_dispatch_request()
  File "/www/blog/venv/lib/python3.6/site-packages/flask/app.py", line 1815, in full_dispatch_request
    rv = self.handle_user_exception(e)
  File "/www/blog/venv/lib/python3.6/site-packages/flask/app.py", line 1718, in handle_user_exception
    reraise(exc_type, exc_value, tb)
  File "/www/blog/venv/lib/python3.6/site-packages/flask/_compat.py", line 35, in reraise
    raise value
  File "/www/blog/venv/lib/python3.6/site-packages/flask/app.py", line 1813, in full_dispatch_request
    rv = self.dispatch_request()
  File "/www/blog/venv/lib/python3.6/site-packages/flask/app.py", line 1799, in dispatch_request
    return self.view_functions[rule.endpoint](**req.view_args)
  File "/www/blog/app/routes.py", line 167, in reset_password_request
    send_password_reset_email(user)
  File "/www/blog/app/email.py", line 13, in send_password_reset_email
    sender=app.config['ADMINS'][0],
NameError: name 'app' is not defined
2018-09-14 14:02:41,490 ERROR: Exception on /reset_password_request [POST] [in /www/blog/venv/lib/python3.6/site-packages/flask/app.py:1761]
Traceback (most recent call last):
  File "/www/blog/venv/lib/python3.6/site-packages/flask/app.py", line 2292, in wsgi_app
    response = self.full_dispatch_request()
  File "/www/blog/venv/lib/python3.6/site-packages/flask/app.py", line 1815, in full_dispatch_request
    rv = self.handle_user_exception(e)
  File "/www/blog/venv/lib/python3.6/site-packages/flask/app.py", line 1718, in handle_user_exception
    reraise(exc_type, exc_value, tb)
  File "/www/blog/venv/lib/python3.6/site-packages/flask/_compat.py", line 35, in reraise
    raise value
  File "/www/blog/venv/lib/python3.6/site-packages/flask/app.py", line 1813, in full_dispatch_request
    rv = self.dispatch_request()
  File "/www/blog/venv/lib/python3.6/site-packages/flask/app.py", line 1799, in dispatch_request
    return self.view_functions[rule.endpoint](**req.view_args)
  File "/www/blog/app/routes.py", line 167, in reset_password_request
    send_password_reset_email(user)
  File "/www/blog/app/email.py", line 13, in send_password_reset_email
    sender=app.config['ADMINS'][0],
NameError: name 'app' is not defined
2018-09-14 14:07:41,631 INFO: Microblog startup [in /www/blog/app/__init__.py:47]
2018-09-14 14:07:57,349 ERROR: Exception on /reset_password_request [POST] [in /www/blog/venv/lib/python3.6/site-packages/flask/app.py:1761]
Traceback (most recent call last):
  File "/www/blog/venv/lib/python3.6/site-packages/flask/app.py", line 2292, in wsgi_app
    response = self.full_dispatch_request()
  File "/www/blog/venv/lib/python3.6/site-packages/flask/app.py", line 1815, in full_dispatch_request
    rv = self.handle_user_exception(e)
  File "/www/blog/venv/lib/python3.6/site-packages/flask/app.py", line 1718, in handle_user_exception
    reraise(exc_type, exc_value, tb)
  File "/www/blog/venv/lib/python3.6/site-packages/flask/_compat.py", line 35, in reraise
    raise value
  File "/www/blog/venv/lib/python3.6/site-packages/flask/app.py", line 1813, in full_dispatch_request
    rv = self.dispatch_request()
  File "/www/blog/venv/lib/python3.6/site-packages/flask/app.py", line 1799, in dispatch_request
    return self.view_functions[rule.endpoint](**req.view_args)
  File "/www/blog/app/routes.py", line 167, in reset_password_request
    send_password_reset_email(user)
  File "/www/blog/app/email.py", line 13, in send_password_reset_email
    sender=app.config['ADMINS'][0],
NameError: name 'app' is not defined
2018-09-14 14:09:52,170 INFO: Microblog startup [in /www/blog/app/__init__.py:47]
2018-09-14 14:10:46,514 INFO: Microblog startup [in /www/blog/app/__init__.py:47]
2018-09-14 14:10:52,055 ERROR: Exception on /reset_password_request [POST] [in /www/blog/venv/lib/python3.6/site-packages/flask/app.py:1761]
Traceback (most recent call last):
  File "/www/blog/venv/lib/python3.6/site-packages/flask/app.py", line 2292, in wsgi_app
    response = self.full_dispatch_request()
  File "/www/blog/venv/lib/python3.6/site-packages/flask/app.py", line 1815, in full_dispatch_request
    rv = self.handle_user_exception(e)
  File "/www/blog/venv/lib/python3.6/site-packages/flask/app.py", line 1718, in handle_user_exception
    reraise(exc_type, exc_value, tb)
  File "/www/blog/venv/lib/python3.6/site-packages/flask/_compat.py", line 35, in reraise
    raise value
  File "/www/blog/venv/lib/python3.6/site-packages/flask/app.py", line 1813, in full_dispatch_request
    rv = self.dispatch_request()
  File "/www/blog/venv/lib/python3.6/site-packages/flask/app.py", line 1799, in dispatch_request
    return self.view_functions[rule.endpoint](**req.view_args)
  File "/www/blog/app/routes.py", line 167, in reset_password_request
    send_password_reset_email(user)
  File "/www/blog/app/email.py", line 18, in send_password_reset_email
    sender=app.config['ADMINS'][0],
NameError: name 'app' is not defined
